Workbook

Sheet Low
A1: Country | B1: Austria | C1: Belgium | D1: Australia | E1: Bulgaria | F1: Canada | G1: Czech Republic | H1: Denmark | I1: Finland | J1: France | K1: Germany | L1: Greece | M1: Hungary | N1: Ireland | O1: Italy | P1: Japan | Q1: Latvia | R1: Lithuania | S1: Netherlands | T1: New Zealand | U1: Norway | V1: Poland | W1: Portugal | X1: Romania | Y1: Slovenia | Z1: Spain | AA1: Sweden | AB1: Switzerland | AC1: Turkey | AD1: United Kingdom | AE1: US | AF1: China | AG1: South Korea | AH1: India | AI1: Indonesia | AJ1: Malaysia | AK1: Pakistan | AL1: Philippines | AM1: Singapore | AN1: Taiwan | AO1: Thailand | AP1: Vietnam | AQ1: Iran | AR1: Israel | AS1: Kenya | AT1: Nigeria | AU1: Oman | AV1: Saudi Arabia | AW1: South Africa | AX1: UAE | AY1: Argentina | AZ1: Brazil | BA1: Chile | BB1: Colombia | BC1: Mexico | BD1: Peru | BE1: Russia | BF1: Ukraine
A3: Year
A5: 2028 | B5: 9.3561198e+08 | C5: 9.5551862e+08 | D5: 7.8231754e+09 | E5: 5.9719913e+08 | F5: 3.0905096e+09 | G5: 1.0351452e+09 | H5: 1.154585e+09 | I5: 1.5527178e+09 | J5: 5.4345121e+09 | K5: 9.0973335e+09 | L5: 3.9813276e+08 | M5: 3.7822612e+08 | N5: 2.4485165e+09 | O5: 3.5632882e+09 | P5: 5.5577772e+09 | Q5: 4.9766595e+08 | R5: 3.7822612e+08 | S5: 3.8220745e+09 | T5: 1.6612921e+09 | U5: 1.4730912e+09 | V5: 1.7517841e+09 | W5: 8.3607879e+08 | X5: 1.1943983e+09 | Y5: 4.1803939e+08 | Z5: 3.4239417e+09 | AA5: 2.0503837e+09 | AB5: 2.2693567e+09 | AC5: 1.6522509e+09 | AD5: 8.8385472e+09 | AE5: 1.8905616e+11 | AF5: 9.9982671e+10 | AG5: 2.5372461e+09 | AH5: 8.0044073e+09 | AI5: 4.2891541e+09 | AJ5: 3.2621735e+09 | AK5: 6.6451683e+08 | AL5: 7.5513277e+08 | AM5: 2.2653983e+09 | AN5: 6.6451683e+08 | AO5: 1.5102655e+09 | AP5: 8.7595401e+08 | AQ5: 1.0774232e+08 | AR5: 3.016785e+08 | AS5: 2.1617256e+08 | AT5: 1.9341756e+08 | AU5: 80806740 | AV5: 2.3164599e+08 | AW5: 6.3714018e+08 | AX5: 3.016785e+08 | AY5: 1.3045978e+08 | AZ5: 7.0985471e+08 | BA5: 2.4557136e+08 | BB5: 1.534821e+08 | BC5: 6.582674e+08 | BD5: 57555787 | BE5: 4.3676883e+09 | BF5: 7.365456e+08
A6: 2029 | B6: 1.1397646e+09 | C6: 1.164015e+09 | D6: 9.7838676e+09 | E6: 7.2750935e+08 | F6: 3.792218e+09 | G6: 1.2610162e+09 | H6: 1.4065181e+09 | I6: 1.8915243e+09 | J6: 6.6203351e+09 | K6: 1.1082392e+10 | L6: 4.8500623e+08 | M6: 4.6075592e+08 | N6: 2.9827883e+09 | O6: 4.3408058e+09 | P6: 6.9507013e+09 | Q6: 6.0625779e+08 | R6: 4.6075592e+08 | S6: 4.6560598e+09 | T6: 2.0776553e+09 | U6: 1.7945231e+09 | V6: 2.1340274e+09 | W6: 1.0185131e+09 | X6: 1.4550187e+09 | Y6: 5.0925654e+08 | Z6: 4.1710536e+09 | AA6: 2.4977821e+09 | AB6: 2.7645355e+09 | AC6: 2.0127759e+09 | AD6: 1.0767138e+10 | AE6: 2.3760469e+11 | AF6: 1.284398e+11 | AG6: 3.1731462e+09 | AH6: 1.0010521e+10 | AI6: 5.3641282e+09 | AJ6: 4.0797594e+09 | AK6: 8.3106211e+08 | AL6: 9.4438876e+08 | AM6: 2.8331663e+09 | AN6: 8.3106211e+08 | AO6: 1.8887775e+09 | AP6: 1.095491e+09 | AQ6: 1.3309227e+08 | AR6: 3.7265834e+08 | AS6: 2.687302e+08 | AT6: 2.4044281e+08 | AU6: 99819200 | AV6: 2.8614837e+08 | AW6: 7.9204692e+08 | AX6: 3.7265834e+08 | AY6: 1.6177454e+08 | AZ6: 8.8024384e+08 | BA6: 3.0451679e+08 | BB6: 1.9032299e+08 | BC6: 8.0772874e+08 | BD6: 71371122 | BE6: 5.4014955e+09 | BF6: 8.9726153e+08
A7: 2030 | B7: 1.2770386e+09 | C7: 1.3042096e+09 | D7: 1.1283829e+10 | E7: 8.15131e+08 | F7: 4.2830107e+09 | G7: 1.4128937e+09 | H7: 1.5759199e+09 | I7: 2.1193406e+09 | J7: 7.4176921e+09 | K7: 1.2417162e+10 | L7: 5.4342067e+08 | M7: 5.1624964e+08 | N7: 3.3420371e+09 | O7: 4.863615e+09 | P7: 8.0163108e+09 | Q7: 6.7927584e+08 | R7: 5.1624964e+08 | S7: 5.2168384e+09 | T7: 2.3961798e+09 | U7: 2.0106565e+09 | V7: 2.3910509e+09 | W7: 1.1411834e+09 | X7: 1.630262e+09 | Y7: 5.705917e+08 | Z7: 4.6734178e+09 | AA7: 2.7986164e+09 | AB7: 3.0974978e+09 | AC7: 2.2551958e+09 | AD7: 1.2063939e+10 | AE7: 2.7551537e+11 | AF7: 1.5254729e+11 | AG7: 3.6596201e+09 | AH7: 1.154523e+10 | AI7: 6.1865007e+09 | AJ7: 4.7052259e+09 | AK7: 9.5847194e+08 | AL7: 1.0891727e+09 | AM7: 3.267518e+09 | AN7: 9.5847194e+08 | AO7: 2.1783453e+09 | AP7: 1.2634403e+09 | AQ7: 1.5142791e+08 | AR7: 4.2399814e+08 | AS7: 3.078885e+08 | AT7: 2.7547918e+08 | AU7: 1.1357093e+08 | AV7: 3.2557e+08 | AW7: 9.0746083e+08 | AX7: 4.2399814e+08 | AY7: 1.8484051e+08 | AZ7: 1.0057498e+09 | BA7: 3.4793508e+08 | BB7: 2.1745943e+08 | BC7: 9.1226582e+08 | BD7: 81547285 | BE7: 6.1533664e+09 | BF7: 1.0053282e+09
A8: 2031 | B8: 1.3263278e+09 | C8: 1.3545476e+09 | D8: 1.2060947e+10 | E8: 8.4659222e+08 | F8: 4.4840841e+09 | G8: 1.4674265e+09 | H8: 1.636745e+09 | I8: 2.2011398e+09 | J8: 7.7039892e+09 | K8: 1.2896421e+10 | L8: 5.6439481e+08 | M8: 5.3617507e+08 | N8: 3.4710281e+09 | O8: 5.0513336e+09 | P8: 8.5683945e+09 | Q8: 7.0549352e+08 | R8: 5.3617507e+08 | S8: 5.4181902e+09 | T8: 2.5612049e+09 | U8: 2.0882608e+09 | V8: 2.4833372e+09 | W8: 1.1852291e+09 | X8: 1.6931844e+09 | Y8: 5.9261455e+08 | Z8: 4.8537954e+09 | AA8: 2.9066333e+09 | AB8: 3.2170504e+09 | AC8: 2.3422385e+09 | AD8: 1.2529565e+10 | AE8: 2.9604951e+11 | AF8: 1.6775158e+11 | AG8: 3.9116584e+09 | AH8: 1.2340351e+10 | AI8: 6.6125653e+09 | AJ8: 5.029275e+09 | AK8: 1.024482e+09 | AL8: 1.164184e+09 | AM8: 3.4925521e+09 | AN8: 1.024482e+09 | AO8: 2.3283681e+09 | AP8: 1.3504535e+09 | AQ8: 1.59704e+08 | AR8: 4.4717119e+08 | AS8: 3.2696133e+08 | AT8: 2.9254435e+08 | AU8: 1.19778e+08 | AV8: 3.433636e+08 | AW8: 9.6367549e+08 | AX8: 4.4717119e+08 | AY8: 1.9576024e+08 | AZ8: 1.065166e+09 | BA8: 3.6848987e+08 | BB8: 2.3030617e+08 | BC8: 9.5509373e+08 | BD8: 86364814 | BE8: 6.4977672e+09 | BF8: 1.0441304e+09
A9: 2032 | B9: 1.2883583e+09 | C9: 1.3157702e+09 | D9: 1.2037936e+10 | E9: 8.2235636e+08 | F9: 4.389123e+09 | G9: 1.4254177e+09 | H9: 1.589889e+09 | I9: 2.1381265e+09 | J9: 7.4834428e+09 | K9: 1.2527228e+10 | L9: 5.4823757e+08 | M9: 5.2082569e+08 | N9: 3.3716611e+09 | O9: 4.9067263e+09 | P9: 8.5520473e+09 | Q9: 6.8529696e+08 | R9: 5.2082569e+08 | S9: 5.2630807e+09 | T9: 2.5563185e+09 | U9: 2.028479e+09 | V9: 2.4122453e+09 | W9: 1.1512989e+09 | X9: 1.6447127e+09 | Y9: 5.7564945e+08 | Z9: 4.7148431e+09 | AA9: 2.8234235e+09 | AB9: 3.1249542e+09 | AC9: 2.2751859e+09 | AD9: 1.2170874e+10 | AE9: 2.9693719e+11 | AF9: 1.7185323e+11 | AG9: 3.9041955e+09 | AH9: 1.2316807e+10 | AI9: 6.5999496e+09 | AJ9: 5.01968e+09 | AK9: 1.0225274e+09 | AL9: 1.161963e+09 | AM9: 3.4858889e+09 | AN9: 1.0225274e+09 | AO9: 2.3239259e+09 | AP9: 1.347877e+09 | AQ9: 1.5741139e+08 | AR9: 4.407519e+08 | AS9: 3.2436291e+08 | AT9: 2.9021945e+08 | AU9: 1.1805854e+08 | AV9: 3.3843449e+08 | AW9: 9.5601701e+08 | AX9: 4.407519e+08 | AY9: 1.9371184e+08 | AZ9: 1.0540203e+09 | BA9: 3.6463406e+08 | BB9: 2.2789629e+08 | BC9: 9.3486735e+08 | BD9: 85461108 | BE9: 6.412024e+09 | BF9: 1.0142395e+09
A10: 2033 | B10: 1.2562433e+09 | C10: 1.2829719e+09 | D10: 1.197041e+10 | E10: 8.0185744e+08 | F10: 4.3034936e+09 | G10: 1.3898862e+09 | H10: 1.5502577e+09 | I10: 2.0848293e+09 | J10: 7.2969027e+09 | K10: 1.2214962e+10 | L10: 5.3457163e+08 | M10: 5.0784304e+08 | N10: 3.2876155e+09 | O10: 4.7844161e+09 | P10: 8.5040752e+09 | Q10: 6.6821453e+08 | R10: 5.0784304e+08 | S10: 5.1318876e+09 | T10: 2.541979e+09 | U10: 1.977915e+09 | V10: 2.3521152e+09 | W10: 1.1226004e+09 | X10: 1.6037149e+09 | Y10: 5.6130021e+08 | Z10: 4.597316e+09 | AA10: 2.7530439e+09 | AB10: 3.0470583e+09 | AC10: 2.2184722e+09 | AD10: 1.186749e+10 | AE10: 2.9631494e+11 | AF10: 1.7411362e+11 | AG10: 3.8822952e+09 | AH10: 1.2247717e+10 | AI10: 6.5629276e+09 | AJ10: 4.9915224e+09 | AK10: 1.0167916e+09 | AL10: 1.155445e+09 | AM10: 3.466335e+09 | AN10: 1.0167916e+09 | AO10: 2.31089e+09 | AP10: 1.3403162e+09 | AQ10: 1.551179e+08 | AR10: 4.3433011e+08 | AS10: 3.2113592e+08 | AT10: 2.8733213e+08 | AU10: 1.1633842e+08 | AV10: 3.3350348e+08 | AW10: 9.4650585e+08 | AX10: 4.3433011e+08 | AY10: 1.9143349e+08 | AZ10: 1.0416234e+09 | BA10: 3.603454e+08 | BB10: 2.2521588e+08 | BC10: 9.1662861e+08 | BD10: 84455953 | BE10: 6.3239706e+09 | BF10: 9.8895751e+08
A11: 2034 | B11: 1.2386253e+09 | C11: 1.2649791e+09 | D11: 1.1936376e+10 | E11: 7.9061192e+08 | F11: 4.256645e+09 | G11: 1.370394e+09 | H11: 1.5285164e+09 | I11: 2.055591e+09 | J11: 7.1945685e+09 | K11: 1.2043655e+10 | L11: 5.2707462e+08 | M11: 5.0072088e+08 | N11: 3.2415089e+09 | O11: 4.7173178e+09 | P11: 8.4798967e+09 | Q11: 6.5884327e+08 | R11: 5.0072088e+08 | S11: 5.0599163e+09 | T11: 2.5347517e+09 | U11: 1.9501761e+09 | V11: 2.3191283e+09 | W11: 1.1068567e+09 | X11: 1.5812238e+09 | Y11: 5.5342835e+08 | Z11: 4.5328417e+09 | AA11: 2.7144343e+09 | AB11: 3.0043253e+09 | AC11: 2.1873597e+09 | AD11: 1.1701056e+10 | AE11: 2.9607453e+11 | AF11: 1.7550697e+11 | AG11: 3.8712572e+09 | AH11: 1.2212895e+10 | AI11: 6.5442681e+09 | AJ11: 4.9773307e+09 | AK11: 1.0139007e+09 | AL11: 1.1521599e+09 | AM11: 3.4564796e+09 | AN11: 1.0139007e+09 | AO11: 2.3043198e+09 | AP11: 1.3365055e+09 | AQ11: 1.5387279e+08 | AR11: 4.3084381e+08 | AS11: 3.194169e+08 | AT11: 2.8579407e+08 | AU11: 1.1540459e+08 | AV11: 3.308265e+08 | AW11: 9.4143928e+08 | AX11: 4.3084381e+08 | AY11: 1.90208e+08 | AZ11: 1.0349553e+09 | BA11: 3.5803858e+08 | BB11: 2.2377411e+08 | BC11: 9.0665002e+08 | BD11: 83915292 | BE11: 6.2762742e+09 | BF11: 9.7508804e+08
A12: 2035 | B12: 1.2339923e+09 | C12: 1.2602474e+09 | D12: 1.192809e+10 | E12: 7.8765464e+08 | F12: 4.2443631e+09 | G12: 1.365268e+09 | H12: 1.522799e+09 | I12: 2.0479021e+09 | J12: 7.1676573e+09 | K12: 1.1998606e+10 | L12: 5.251031e+08 | M12: 4.9884794e+08 | N12: 3.229384e+09 | O12: 4.6996727e+09 | P12: 8.4740097e+09 | Q12: 6.5637887e+08 | R12: 4.9884794e+08 | S12: 5.0409897e+09 | T12: 2.532992e+09 | U12: 1.9428815e+09 | V12: 2.3104536e+09 | W12: 1.1027165e+09 | X12: 1.5753093e+09 | Y12: 5.5135825e+08 | Z12: 4.5158866e+09 | AA12: 2.7042809e+09 | AB12: 2.9930876e+09 | AC12: 2.1791778e+09 | AD12: 1.1657289e+10 | AE12: 2.9603284e+11 | AF12: 1.7590357e+11 | AG12: 3.8685696e+09 | AH12: 1.2204416e+10 | AI12: 6.5397248e+09 | AJ12: 4.9738752e+09 | AK12: 1.0131968e+09 | AL12: 1.15136e+09 | AM12: 3.45408e+09 | AN12: 1.0131968e+09 | AO12: 2.30272e+09 | AP12: 1.3355776e+09 | AQ12: 1.5354869e+08 | AR12: 4.2993632e+08 | AS12: 3.1897678e+08 | AT12: 2.8540028e+08 | AU12: 1.1516152e+08 | AV12: 3.3012968e+08 | AW12: 9.4014209e+08 | AX12: 4.2993632e+08 | AY12: 1.8989157e+08 | AZ12: 1.0332336e+09 | BA12: 3.5744296e+08 | BB12: 2.2340185e+08 | BC12: 9.0403403e+08 | BD12: 83775694 | BE12: 6.2638832e+09 | BF12: 9.7144073e+08
A14: Solar Capacity (MW) | BH14: Total Solar Capacity (GW)
A16: 2028 | B16: =B5/'Output-Calculation-sheet'!B4*'Output-Calculation-sheet'!B22 -> 0 | C16: =C5/'Output-Calculation-sheet'!C4*'Output-Calculation-sheet'!C22 -> 0 | D16: =D5/'Output-Calculation-sheet'!D4*'Output-Calculation-sheet'!D22 -> 84.81133 | E16: =E5/'Output-Calculation-sheet'!E4*'Output-Calculation-sheet'!E22 -> 5.4013568 | F16: =F5/'Output-Calculation-sheet'!F4*'Output-Calculation-sheet'!F22 -> 24.882504 | G16: =G5/'Output-Calculation-sheet'!G4*'Output-Calculation-sheet'!G22 -> 0 | H16: =H5/'Output-Calculation-sheet'!H4*'Output-Calculation-sheet'!H22 -> 0 | I16: =I5/'Output-Calculation-sheet'!I4*'Output-Calculation-sheet'!I22 -> 0 | ... BF16: =BF5/'Output-Calculation-sheet'!BF4*'Output-Calculation-sheet'!BF22 -> 0 | BH16: =SUM(B16:BF16)/1000 -> 12.090771
A17: 2029 | B17: =B6/'Output-Calculation-sheet'!B5*'Output-Calculation-sheet'!B23 -> 0 | C17: =C6/'Output-Calculation-sheet'!C5*'Output-Calculation-sheet'!C23 -> 0 | D17: =D6/'Output-Calculation-sheet'!D5*'Output-Calculation-sheet'!D23 -> 163.51894 | E17: =E6/'Output-Calculation-sheet'!E5*'Output-Calculation-sheet'!E23 -> 10.765362 | F17: =F6/'Output-Calculation-sheet'!F5*'Output-Calculation-sheet'!F23 -> 52.378094 | G17: =G6/'Output-Calculation-sheet'!G5*'Output-Calculation-sheet'!G23 -> 0 | H17: =H6/'Output-Calculation-sheet'!H5*'Output-Calculation-sheet'!H23 -> 0 | I17: =I6/'Output-Calculation-sheet'!I5*'Output-Calculation-sheet'!I23 -> 0 | ... BF17: =BF6/'Output-Calculation-sheet'!BF5*'Output-Calculation-sheet'!BF23 -> 0 | BH17: =SUM(B17:BF17)/1000 -> 27.077619
A18: 2030 | B18: =B7/'Output-Calculation-sheet'!B6*'Output-Calculation-sheet'!B24 -> 0 | C18: =C7/'Output-Calculation-sheet'!C6*'Output-Calculation-sheet'!C24 -> 0 | D18: =D7/'Output-Calculation-sheet'!D6*'Output-Calculation-sheet'!D24 -> 199.74272 | E18: =E7/'Output-Calculation-sheet'!E6*'Output-Calculation-sheet'!E24 -> 14.316953 | F18: =F7/'Output-Calculation-sheet'!F6*'Output-Calculation-sheet'!F24 -> 74.087201 | G18: =G7/'Output-Calculation-sheet'!G6*'Output-Calculation-sheet'!G24 -> 0 | H18: =H7/'Output-Calculation-sheet'!H6*'Output-Calculation-sheet'!H24 -> 0 | I18: =I7/'Output-Calculation-sheet'!I6*'Output-Calculation-sheet'!I24 -> 0 | ... BF18: =BF7/'Output-Calculation-sheet'!BF6*'Output-Calculation-sheet'!BF24 -> 0 | BH18: =SUM(B18:BF18)/1000 -> 40.352827
A19: 2031 | B19: =B8/'Output-Calculation-sheet'!B7*'Output-Calculation-sheet'!B25 -> 0 | C19: =C8/'Output-Calculation-sheet'!C7*'Output-Calculation-sheet'!C25 -> 0 | D19: =D8/'Output-Calculation-sheet'!D7*'Output-Calculation-sheet'!D25 -> 154.0734 | E19: =E8/'Output-Calculation-sheet'!E7*'Output-Calculation-sheet'!E25 -> 0 | F19: =F8/'Output-Calculation-sheet'!F7*'Output-Calculation-sheet'!F25 -> 74.629543 | G19: =G8/'Output-Calculation-sheet'!G7*'Output-Calculation-sheet'!G25 -> 0 | H19: =H8/'Output-Calculation-sheet'!H7*'Output-Calculation-sheet'!H25 -> 0 | I19: =I8/'Output-Calculation-sheet'!I7*'Output-Calculation-sheet'!I25 -> 0 | ... BF19: =BF8/'Output-Calculation-sheet'!BF7*'Output-Calculation-sheet'!BF25 -> 0 | BH19: =SUM(B19:BF19)/1000 -> 47.732971
A20: 2032 | B20: =B9/'Output-Calculation-sheet'!B8*'Output-Calculation-sheet'!B26 -> 0 | C20: =C9/'Output-Calculation-sheet'!C8*'Output-Calculation-sheet'!C26 -> 0 | D20: =D9/'Output-Calculation-sheet'!D8*'Output-Calculation-sheet'!D26 -> 51.441714 | E20: =E9/'Output-Calculation-sheet'!E8*'Output-Calculation-sheet'!E26 -> 0 | F20: =F9/'Output-Calculation-sheet'!F8*'Output-Calculation-sheet'!F26 -> 56.756507 | G20: =G9/'Output-Calculation-sheet'!G8*'Output-Calculation-sheet'!G26 -> 0 | H20: =H9/'Output-Calculation-sheet'!H8*'Output-Calculation-sheet'!H26 -> 0 | I20: =I9/'Output-Calculation-sheet'!I8*'Output-Calculation-sheet'!I26 -> 0 | ... BF20: =BF9/'Output-Calculation-sheet'!BF8*'Output-Calculation-sheet'!BF26 -> 0 | BH20: =SUM(B20:BF20)/1000 -> 47.588486
A21: 2033 | B21: =B10/'Output-Calculation-sheet'!B9*'Output-Calculation-sheet'!B27 -> 0 | C21: =C10/'Output-Calculation-sheet'!C9*'Output-Calculation-sheet'!C27 -> 0 | D21: =D10/'Output-Calculation-sheet'!D9*'Output-Calculation-sheet'!D27 -> 0 | E21: =E10/'Output-Calculation-sheet'!E9*'Output-Calculation-sheet'!E27 -> 0 | F21: =F10/'Output-Calculation-sheet'!F9*'Output-Calculation-sheet'!F27 -> 25.375096 | G21: =G10/'Output-Calculation-sheet'!G9*'Output-Calculation-sheet'!G27 -> 0 | H21: =H10/'Output-Calculation-sheet'!H9*'Output-Calculation-sheet'!H27 -> 0 | I21: =I10/'Output-Calculation-sheet'!I9*'Output-Calculation-sheet'!I27 -> 0 | ... BF21: =BF10/'Output-Calculation-sheet'!BF9*'Output-Calculation-sheet'!BF27 -> 0 | BH21: =SUM(B21:BF21)/1000 -> 43.494752
A22: 2034 | B22: =B11/'Output-Calculation-sheet'!B10*'Output-Calculation-sheet'!B28 -> 33.327923 | C22: =C11/'Output-Calculation-sheet'!C10*'Output-Calculation-sheet'!C28 -> 0 | D22: =D11/'Output-Calculation-sheet'!D10*'Output-Calculation-sheet'!D28 -> 0 | E22: =E11/'Output-Calculation-sheet'!E10*'Output-Calculation-sheet'!E28 -> 0 | F22: =F11/'Output-Calculation-sheet'!F10*'Output-Calculation-sheet'!F28 -> 0 | G22: =G11/'Output-Calculation-sheet'!G10*'Output-Calculation-sheet'!G28 -> 0 | H22: =H11/'Output-Calculation-sheet'!H10*'Output-Calculation-sheet'!H28 -> 0 | I22: =I11/'Output-Calculation-sheet'!I10*'Output-Calculation-sheet'!I28 -> 35.969096 | ... BF22: =BF11/'Output-Calculation-sheet'!BF10*'Output-Calculation-sheet'!BF28 -> 0 | BH22: =SUM(B22:BF22)/1000 -> 35.074018
A23: 2035 | B23: =B12/'Output-Calculation-sheet'!B11*'Output-Calculation-sheet'!B29 -> 127.2432 | C23: =C12/'Output-Calculation-sheet'!C11*'Output-Calculation-sheet'!C29 -> 0 | D23: =D12/'Output-Calculation-sheet'!D11*'Output-Calculation-sheet'!D29 -> 0 | E23: =E12/'Output-Calculation-sheet'!E11*'Output-Calculation-sheet'!E29 -> 0 | F23: =F12/'Output-Calculation-sheet'!F11*'Output-Calculation-sheet'!F29 -> 0 | G23: =G12/'Output-Calculation-sheet'!G11*'Output-Calculation-sheet'!G29 -> 0 | H23: =H12/'Output-Calculation-sheet'!H11*'Output-Calculation-sheet'!H29 -> 0 | I23: =I12/'Output-Calculation-sheet'!I11*'Output-Calculation-sheet'!I29 -> 238.68073 | ... BF23: =BF12/'Output-Calculation-sheet'!BF11*'Output-Calculation-sheet'!BF29 -> 0 | BH23: =SUM(B23:BF23)/1000 -> 23.25571
A25: Wind Capacity (MW) | BH25: Total Wind Capacity (GW)
A27: 2028 | B27: =B5/'Output-Calculation-sheet'!B4*'Output-Calculation-sheet'!B13 -> 32.092991 | C27: =C5/'Output-Calculation-sheet'!C4*'Output-Calculation-sheet'!C13 -> 15.322326 | D27: =D5/'Output-Calculation-sheet'!D4*'Output-Calculation-sheet'!D13 -> 79.914696 | E27: =E5/'Output-Calculation-sheet'!E4*'Output-Calculation-sheet'!E13 -> 12.14953 | F27: =F5/'Output-Calculation-sheet'!F4*'Output-Calculation-sheet'!F13 -> 42.582805 | G27: =G5/'Output-Calculation-sheet'!G4*'Output-Calculation-sheet'!G13 -> 18.751996 | H27: =H5/'Output-Calculation-sheet'!H4*'Output-Calculation-sheet'!H13 -> 15.393637 | I27: =I5/'Output-Calculation-sheet'!I4*'Output-Calculation-sheet'!I13 -> 60.427133 | ... BF27: =BF5/'Output-Calculation-sheet'!BF4*'Output-Calculation-sheet'!BF13 -> 10.359566 | BH27: =SUM(B27:BF27)/1000 -> 4.7399475
A28: 2029 | B28: =B6/'Output-Calculation-sheet'!B5*'Output-Calculation-sheet'!B14 -> 78.191509 | C28: =C6/'Output-Calculation-sheet'!C5*'Output-Calculation-sheet'!C14 -> 37.331384 | D28: =D6/'Output-Calculation-sheet'!D5*'Output-Calculation-sheet'!D14 -> 215.52909 | E28: =E6/'Output-Calculation-sheet'!E5*'Output-Calculation-sheet'!E14 -> 30.293495 | F28: =F6/'Output-Calculation-sheet'!F5*'Output-Calculation-sheet'!F14 -> 108.30522 | G28: =G6/'Output-Calculation-sheet'!G5*'Output-Calculation-sheet'!G14 -> 45.687448 | H28: =H6/'Output-Calculation-sheet'!H5*'Output-Calculation-sheet'!H14 -> 37.505127 | I28: =I6/'Output-Calculation-sheet'!I5*'Output-Calculation-sheet'!I14 -> 147.2215 | ... BF28: =BF6/'Output-Calculation-sheet'!BF5*'Output-Calculation-sheet'!BF14 -> 25.240093 | BH28: =SUM(B28:BF28)/1000 -> 12.59328
A29: 2030 | B29: =B7/'Output-Calculation-sheet'!B6*'Output-Calculation-sheet'!B15 -> 131.41341 | C29: =C7/'Output-Calculation-sheet'!C6*'Output-Calculation-sheet'!C15 -> 62.741397 | D29: =D7/'Output-Calculation-sheet'!D6*'Output-Calculation-sheet'!D15 -> 399.60348 | E29: =E7/'Output-Calculation-sheet'!E6*'Output-Calculation-sheet'!E15 -> 52.004534 | F29: =F7/'Output-Calculation-sheet'!F6*'Output-Calculation-sheet'!F15 -> 189.89161 | G29: =G7/'Output-Calculation-sheet'!G6*'Output-Calculation-sheet'!G15 -> 76.785106 | H29: =H7/'Output-Calculation-sheet'!H6*'Output-Calculation-sheet'!H15 -> 63.030322 | I29: =I7/'Output-Calculation-sheet'!I6*'Output-Calculation-sheet'!I15 -> 247.7208 | ... BF29: =BF7/'Output-Calculation-sheet'!BF6*'Output-Calculation-sheet'!BF15 -> 42.420038 | BH29: =SUM(B29:BF29)/1000 -> 23.195864
A30: 2031 | B30: =B8/'Output-Calculation-sheet'!B7*'Output-Calculation-sheet'!B16 -> 186.73192 | C30: =C8/'Output-Calculation-sheet'!C7*'Output-Calculation-sheet'!C16 -> 86.881667 | D30: =D8/'Output-Calculation-sheet'!D7*'Output-Calculation-sheet'!D16 -> 611.52021 | E30: =E8/'Output-Calculation-sheet'!E7*'Output-Calculation-sheet'!E16 -> 77.750055 | F30: =F8/'Output-Calculation-sheet'!F7*'Output-Calculation-sheet'!F16 -> 277.66774 | G30: =G8/'Output-Calculation-sheet'!G7*'Output-Calculation-sheet'!G16 -> 106.33454 | H30: =H8/'Output-Calculation-sheet'!H7*'Output-Calculation-sheet'!H16 -> 87.285163 | I30: =I8/'Output-Calculation-sheet'!I7*'Output-Calculation-sheet'!I16 -> 347.89 | ... BF30: =BF8/'Output-Calculation-sheet'!BF7*'Output-Calculation-sheet'!BF16 -> 58.743071 | BH30: =SUM(B30:BF30)/1000 -> 35.966494
A31: 2032 | B31: =B9/'Output-Calculation-sheet'!B8*'Output-Calculation-sheet'!B17 -> 241.75381 | C31: =C9/'Output-Calculation-sheet'!C8*'Output-Calculation-sheet'!C17 -> 105.49364 | D31: =D9/'Output-Calculation-sheet'!D8*'Output-Calculation-sheet'!D17 -> 808.22888 | E31: =E9/'Output-Calculation-sheet'!E8*'Output-Calculation-sheet'!E17 -> 94.539126 | F31: =F9/'Output-Calculation-sheet'!F8*'Output-Calculation-sheet'!F17 -> 354.86408 | G31: =G9/'Output-Calculation-sheet'!G8*'Output-Calculation-sheet'!G17 -> 129.11236 | H31: =H9/'Output-Calculation-sheet'!H8*'Output-Calculation-sheet'!H17 -> 105.98378 | I31: =I9/'Output-Calculation-sheet'!I8*'Output-Calculation-sheet'!I17 -> 436.15775 | ... BF31: =BF9/'Output-Calculation-sheet'!BF8*'Output-Calculation-sheet'!BF17 -> 71.326751 | BH31: =SUM(B31:BF31)/1000 -> 48.229986
A32: 2033 | B32: =B10/'Output-Calculation-sheet'!B9*'Output-Calculation-sheet'!B18 -> 312.55162 | C32: =C10/'Output-Calculation-sheet'!C9*'Output-Calculation-sheet'!C18 -> 123.43723 | D32: =D10/'Output-Calculation-sheet'!D9*'Output-Calculation-sheet'!D18 -> 984.1817 | E32: =E10/'Output-Calculation-sheet'!E9*'Output-Calculation-sheet'!E18 -> 117.47918 | F32: =F10/'Output-Calculation-sheet'!F9*'Output-Calculation-sheet'!F18 -> 435.65799 | G32: =G10/'Output-Calculation-sheet'!G9*'Output-Calculation-sheet'!G18 -> 151.07221 | H32: =H10/'Output-Calculation-sheet'!H9*'Output-Calculation-sheet'!H18 -> 124.0109 | I32: =I10/'Output-Calculation-sheet'!I9*'Output-Calculation-sheet'!I18 -> 538.26992 | ... BF32: =BF10/'Output-Calculation-sheet'!BF9*'Output-Calculation-sheet'!BF18 -> 83.458543 | BH32: =SUM(B32:BF32)/1000 -> 61.733946
A33: 2034 | B33: =B11/'Output-Calculation-sheet'!B10*'Output-Calculation-sheet'!B19 -> 366.74346 | C33: =C11/'Output-Calculation-sheet'!C10*'Output-Calculation-sheet'!C19 -> 142.24302 | D33: =D11/'Output-Calculation-sheet'!D10*'Output-Calculation-sheet'!D19 -> 1144.9578 | E33: =E11/'Output-Calculation-sheet'!E10*'Output-Calculation-sheet'!E19 -> 148.72316 | F33: =F11/'Output-Calculation-sheet'!F10*'Output-Calculation-sheet'!F19 -> 526.69104 | G33: =G11/'Output-Calculation-sheet'!G10*'Output-Calculation-sheet'!G19 -> 189.09091 | H33: =H11/'Output-Calculation-sheet'!H10*'Output-Calculation-sheet'!H19 -> 142.65085 | I33: =I11/'Output-Calculation-sheet'!I10*'Output-Calculation-sheet'!I19 -> 649.78702 | ... BF33: =BF11/'Output-Calculation-sheet'!BF10*'Output-Calculation-sheet'!BF19 -> 96.000859 | BH33: =SUM(B33:BF33)/1000 -> 77.630044
A34: 2035 | B34: =B12/'Output-Calculation-sheet'!B11*'Output-Calculation-sheet'!B20 -> 362.34061 | C34: =C12/'Output-Calculation-sheet'!C11*'Output-Calculation-sheet'!C20 -> 191.35582 | D34: =D12/'Output-Calculation-sheet'!D11*'Output-Calculation-sheet'!D20 -> 1310.4729 | E34: =E12/'Output-Calculation-sheet'!E11*'Output-Calculation-sheet'!E20 -> 190.32349 | F34: =F12/'Output-Calculation-sheet'!F11*'Output-Calculation-sheet'!F20 -> 647.10745 | G34: =G12/'Output-Calculation-sheet'!G11*'Output-Calculation-sheet'!G20 -> 257.35855 | H34: =H12/'Output-Calculation-sheet'!H11*'Output-Calculation-sheet'!H20 -> 162.41719 | I34: =I12/'Output-Calculation-sheet'!I11*'Output-Calculation-sheet'!I20 -> 708.85216 | ... BF34: =BF12/'Output-Calculation-sheet'!BF11*'Output-Calculation-sheet'!BF20 -> 109.30515 | BH34: =SUM(B34:BF34)/1000 -> 97.221451
A36: DAC Capacity (ktCO2/yr) | BH36: Total DAC Capacity (ktCO2/yr)
A38: 2028 | B38: =B5/'Output-Calculation-sheet'!B4*'Output-Calculation-sheet'!B31*0.0114 -> 0 | C38: =C5/'Output-Calculation-sheet'!C4*'Output-Calculation-sheet'!C31*0.0114 -> 0 | D38: =D5/'Output-Calculation-sheet'!D4*'Output-Calculation-sheet'!D31*0.0114 -> 0 | E38: =E5/'Output-Calculation-sheet'!E4*'Output-Calculation-sheet'!E31*0.0114 -> 0 | F38: =F5/'Output-Calculation-sheet'!F4*'Output-Calculation-sheet'!F31*0.0114 -> 0 | G38: =G5/'Output-Calculation-sheet'!G4*'Output-Calculation-sheet'!G31*0.0114 -> 0 | H38: =H5/'Output-Calculation-sheet'!H4*'Output-Calculation-sheet'!H31*0.0114 -> 0 | I38: =I5/'Output-Calculation-sheet'!I4*'Output-Calculation-sheet'!I31*0.0114 -> 0 | ... BF38: =BF5/'Output-Calculation-sheet'!BF4*'Output-Calculation-sheet'!BF31*0.0114 -> 0 | BH38: =SUM(B38:BF38) -> 5.0622392
A39: 2029 | B39: =B6/'Output-Calculation-sheet'!B5*'Output-Calculation-sheet'!B32*0.0114 -> 0 | C39: =C6/'Output-Calculation-sheet'!C5*'Output-Calculation-sheet'!C32*0.0114 -> 0 | D39: =D6/'Output-Calculation-sheet'!D5*'Output-Calculation-sheet'!D32*0.0114 -> 0 | E39: =E6/'Output-Calculation-sheet'!E5*'Output-Calculation-sheet'!E32*0.0114 -> 0 | F39: =F6/'Output-Calculation-sheet'!F5*'Output-Calculation-sheet'!F32*0.0114 -> 0 | G39: =G6/'Output-Calculation-sheet'!G5*'Output-Calculation-sheet'!G32*0.0114 -> 0 | H39: =H6/'Output-Calculation-sheet'!H5*'Output-Calculation-sheet'!H32*0.0114 -> 0 | I39: =I6/'Output-Calculation-sheet'!I5*'Output-Calculation-sheet'!I32*0.0114 -> 0 | ... BF39: =BF6/'Output-Calculation-sheet'!BF5*'Output-Calculation-sheet'!BF32*0.0114 -> 0 | BH39: =SUM(B39:BF39) -> 10.660751
A40: 2030 | B40: =B7/'Output-Calculation-sheet'!B6*'Output-Calculation-sheet'!B33*0.0114 -> 0 | C40: =C7/'Output-Calculation-sheet'!C6*'Output-Calculation-sheet'!C33*0.0114 -> 0 | D40: =D7/'Output-Calculation-sheet'!D6*'Output-Calculation-sheet'!D33*0.0114 -> 0 | E40: =E7/'Output-Calculation-sheet'!E6*'Output-Calculation-sheet'!E33*0.0114 -> 0 | F40: =F7/'Output-Calculation-sheet'!F6*'Output-Calculation-sheet'!F33*0.0114 -> 0 | G40: =G7/'Output-Calculation-sheet'!G6*'Output-Calculation-sheet'!G33*0.0114 -> 0 | H40: =H7/'Output-Calculation-sheet'!H6*'Output-Calculation-sheet'!H33*0.0114 -> 0 | I40: =I7/'Output-Calculation-sheet'!I6*'Output-Calculation-sheet'!I33*0.0114 -> 0 | ... BF40: =BF7/'Output-Calculation-sheet'!BF6*'Output-Calculation-sheet'!BF33*0.0114 -> 0 | BH40: =SUM(B40:BF40) -> 25.531443
A41: 2031 | B41: =B8/'Output-Calculation-sheet'!B7*'Output-Calculation-sheet'!B34*0.0114 -> 0 | C41: =C8/'Output-Calculation-sheet'!C7*'Output-Calculation-sheet'!C34*0.0114 -> 0 | D41: =D8/'Output-Calculation-sheet'!D7*'Output-Calculation-sheet'!D34*0.0114 -> 0 | E41: =E8/'Output-Calculation-sheet'!E7*'Output-Calculation-sheet'!E34*0.0114 -> 0 | F41: =F8/'Output-Calculation-sheet'!F7*'Output-Calculation-sheet'!F34*0.0114 -> 0 | G41: =G8/'Output-Calculation-sheet'!G7*'Output-Calculation-sheet'!G34*0.0114 -> 0 | H41: =H8/'Output-Calculation-sheet'!H7*'Output-Calculation-sheet'!H34*0.0114 -> 0 | I41: =I8/'Output-Calculation-sheet'!I7*'Output-Calculation-sheet'!I34*0.0114 -> 0 | ... BF41: =BF8/'Output-Calculation-sheet'!BF7*'Output-Calculation-sheet'!BF34*0.0114 -> 0 | BH41: =SUM(B41:BF41) -> 13.056395
A42: 2032 | B42: =B9/'Output-Calculation-sheet'!B8*'Output-Calculation-sheet'!B35*0.0114 -> 0 | C42: =C9/'Output-Calculation-sheet'!C8*'Output-Calculation-sheet'!C35*0.0114 -> 0 | D42: =D9/'Output-Calculation-sheet'!D8*'Output-Calculation-sheet'!D35*0.0114 -> 0 | E42: =E9/'Output-Calculation-sheet'!E8*'Output-Calculation-sheet'!E35*0.0114 -> 0 | F42: =F9/'Output-Calculation-sheet'!F8*'Output-Calculation-sheet'!F35*0.0114 -> 0 | G42: =G9/'Output-Calculation-sheet'!G8*'Output-Calculation-sheet'!G35*0.0114 -> 0 | H42: =H9/'Output-Calculation-sheet'!H8*'Output-Calculation-sheet'!H35*0.0114 -> 0 | I42: =I9/'Output-Calculation-sheet'!I8*'Output-Calculation-sheet'!I35*0.0114 -> 0 | ... BF42: =BF9/'Output-Calculation-sheet'!BF8*'Output-Calculation-sheet'!BF35*0.0114 -> 0 | BH42: =SUM(B42:BF42) -> 9.2152932
A43: 2033 | B43: =B10/'Output-Calculation-sheet'!B9*'Output-Calculation-sheet'!B36*0.0114 -> 0 | C43: =C10/'Output-Calculation-sheet'!C9*'Output-Calculation-sheet'!C36*0.0114 -> 0 | D43: =D10/'Output-Calculation-sheet'!D9*'Output-Calculation-sheet'!D36*0.0114 -> 0 | E43: =E10/'Output-Calculation-sheet'!E9*'Output-Calculation-sheet'!E36*0.0114 -> 0 | F43: =F10/'Output-Calculation-sheet'!F9*'Output-Calculation-sheet'!F36*0.0114 -> 0 | G43: =G10/'Output-Calculation-sheet'!G9*'Output-Calculation-sheet'!G36*0.0114 -> 0 | H43: =H10/'Output-Calculation-sheet'!H9*'Output-Calculation-sheet'!H36*0.0114 -> 0 | I43: =I10/'Output-Calculation-sheet'!I9*'Output-Calculation-sheet'!I36*0.0114 -> 0 | ... BF43: =BF10/'Output-Calculation-sheet'!BF9*'Output-Calculation-sheet'!BF36*0.0114 -> 0 | BH43: =SUM(B43:BF43) -> 0.2010909
A44: 2034 | B44: =B11/'Output-Calculation-sheet'!B10*'Output-Calculation-sheet'!B37*0.0114 -> 0 | C44: =C11/'Output-Calculation-sheet'!C10*'Output-Calculation-sheet'!C37*0.0114 -> 0 | D44: =D11/'Output-Calculation-sheet'!D10*'Output-Calculation-sheet'!D37*0.0114 -> 0 | E44: =E11/'Output-Calculation-sheet'!E10*'Output-Calculation-sheet'!E37*0.0114 -> 0 | F44: =F11/'Output-Calculation-sheet'!F10*'Output-Calculation-sheet'!F37*0.0114 -> 0 | G44: =G11/'Output-Calculation-sheet'!G10*'Output-Calculation-sheet'!G37*0.0114 -> 0 | H44: =H11/'Output-Calculation-sheet'!H10*'Output-Calculation-sheet'!H37*0.0114 -> 0 | I44: =I11/'Output-Calculation-sheet'!I10*'Output-Calculation-sheet'!I37*0.0114 -> 0 | ... BF44: =BF11/'Output-Calculation-sheet'!BF10*'Output-Calculation-sheet'!BF37*0.0114 -> 0 | BH44: =SUM(B44:BF44) -> 0.048047782
A45: 2035 | B45: =B12/'Output-Calculation-sheet'!B11*'Output-Calculation-sheet'!B38*0.0114 -> 0 | C45: =C12/'Output-Calculation-sheet'!C11*'Output-Calculation-sheet'!C38*0.0114 -> 0 | D45: =D12/'Output-Calculation-sheet'!D11*'Output-Calculation-sheet'!D38*0.0114 -> 0 | E45: =E12/'Output-Calculation-sheet'!E11*'Output-Calculation-sheet'!E38*0.0114 -> 0 | F45: =F12/'Output-Calculation-sheet'!F11*'Output-Calculation-sheet'!F38*0.0114 -> 0 | G45: =G12/'Output-Calculation-sheet'!G11*'Output-Calculation-sheet'!G38*0.0114 -> 0 | H45: =H12/'Output-Calculation-sheet'!H11*'Output-Calculation-sheet'!H38*0.0114 -> 0 | I45: =I12/'Output-Calculation-sheet'!I11*'Output-Calculation-sheet'!I38*0.0114 -> 0 | ... BF45: =BF12/'Output-Calculation-sheet'!BF11*'Output-Calculation-sheet'!BF38*0.0114 -> 0 | BH45: =SUM(B45:BF45) -> 0.062905387
A47: Battery Storage Capacity (MWh) | BH47: Total Battery Storage Capacity (GWh)
A49: 2028 | B49: =B5/'Output-Calculation-sheet'!B4*'Output-Calculation-sheet'!B40 -> 0 | C49: =C5/'Output-Calculation-sheet'!C4*'Output-Calculation-sheet'!C40 -> 0 | D49: =D5/'Output-Calculation-sheet'!D4*'Output-Calculation-sheet'!D40 -> 0 | E49: =E5/'Output-Calculation-sheet'!E4*'Output-Calculation-sheet'!E40 -> 0 | F49: =F5/'Output-Calculation-sheet'!F4*'Output-Calculation-sheet'!F40 -> 0 | G49: =G5/'Output-Calculation-sheet'!G4*'Output-Calculation-sheet'!G40 -> 0 | H49: =H5/'Output-Calculation-sheet'!H4*'Output-Calculation-sheet'!H40 -> 0 | I49: =I5/'Output-Calculation-sheet'!I4*'Output-Calculation-sheet'!I40 -> 0 | ... BF49: =BF5/'Output-Calculation-sheet'!BF4*'Output-Calculation-sheet'!BF40 -> 0 | BH49: =SUM(B49:BF49)/1000 -> 6.8392439
A50: 2029 | B50: =B6/'Output-Calculation-sheet'!B5*'Output-Calculation-sheet'!B41 -> 0 | C50: =C6/'Output-Calculation-sheet'!C5*'Output-Calculation-sheet'!C41 -> 0 | D50: =D6/'Output-Calculation-sheet'!D5*'Output-Calculation-sheet'!D41 -> 0 | E50: =E6/'Output-Calculation-sheet'!E5*'Output-Calculation-sheet'!E41 -> 0 | F50: =F6/'Output-Calculation-sheet'!F5*'Output-Calculation-sheet'!F41 -> 0 | G50: =G6/'Output-Calculation-sheet'!G5*'Output-Calculation-sheet'!G41 -> 0 | H50: =H6/'Output-Calculation-sheet'!H5*'Output-Calculation-sheet'!H41 -> 0 | I50: =I6/'Output-Calculation-sheet'!I5*'Output-Calculation-sheet'!I41 -> 0 | ... BF50: =BF6/'Output-Calculation-sheet'!BF5*'Output-Calculation-sheet'!BF41 -> 0 | BH50: =SUM(B50:BF50)/1000 -> 14.45653
...

Sheet Peak 2035-Fast-Medium
A1: Country | B1: Austria | C1: Belgium | D1: Australia | E1: Bulgaria | F1: Canada | G1: Czech Republic | H1: Denmark | I1: Finland | J1: France | K1: Germany | L1: Greece | M1: Hungary | N1: Ireland | O1: Italy | P1: Japan | Q1: Latvia | R1: Lithuania | S1: Netherlands | T1: New Zealand | U1: Norway | V1: Poland | W1: Portugal | X1: Romania | Y1: Slovenia | Z1: Spain | AA1: Sweden | AB1: Switzerland | AC1: Turkey | AD1: United Kingdom | AE1: US | AF1: China | AG1: South Korea | AH1: India | AI1: Indonesia | AJ1: Malaysia | AK1: Pakistan | AL1: Philippines | AM1: Singapore | AN1: Taiwan | AO1: Thailand | AP1: Vietnam | AQ1: Iran | AR1: Israel | AS1: Kenya | AT1: Nigeria | AU1: Oman | AV1: Saudi Arabia | AW1: South Africa | AX1: UAE | AY1: Argentina | AZ1: Brazil | BA1: Chile | BB1: Colombia | BC1: Mexico | BD1: Peru | BE1: Russia | BF1: Ukraine
A3: Year
A5: 2028 | B5: 1.0041388e+09 | C5: 1.0255034e+09 | D5: 8.4236583e+09 | E5: 6.4093964e+08 | F5: 3.3198677e+09 | G5: 1.110962e+09 | H5: 1.23915e+09 | I5: 1.6664431e+09 | J5: 5.8325507e+09 | K5: 9.7636471e+09 | L5: 4.2729309e+08 | M5: 4.0592844e+08 | N5: 2.6278525e+09 | O5: 3.8242732e+09 | P5: 5.984375e+09 | Q5: 5.3411636e+08 | R5: 4.0592844e+08 | S5: 4.1020137e+09 | T5: 1.7888077e+09 | U5: 1.5809844e+09 | V5: 1.8800896e+09 | W5: 8.9731549e+08 | X5: 1.2818793e+09 | Y5: 4.4865775e+08 | Z5: 3.6747206e+09 | AA5: 2.2005594e+09 | AB5: 2.4355706e+09 | AC5: 1.7732663e+09 | AD5: 9.4859066e+09 | AE5: 2.0369138e+11 | AF5: 1.0801266e+11 | AG5: 2.7319973e+09 | AH5: 8.618801e+09 | AI5: 4.6183764e+09 | AJ5: 3.5125679e+09 | AK5: 7.155231e+08 | AL5: 8.1309443e+08 | AM5: 2.4392833e+09 | AN5: 7.155231e+08 | AO5: 1.6261889e+09 | AP5: 9.4318954e+08 | AQ5: 1.1583471e+08 | AR5: 3.2433719e+08 | AS5: 2.325919e+08 | AT5: 2.0810855e+08 | AU5: 86876032 | AV5: 2.4904462e+08 | AW5: 6.8553403e+08 | AX5: 3.2433719e+08 | AY5: 1.403254e+08 | AZ5: 7.6353528e+08 | BA5: 2.6414193e+08 | BB5: 1.6508871e+08 | BC5: 7.0711984e+08 | BD5: 61908266 | BE5: 4.6964069e+09 | BF5: 7.9049222e+08
A6: 2029 | B6: 1.2908581e+09 | C6: 1.3183231e+09 | D6: 1.1140898e+10 | E6: 8.2395196e+08 | F6: 4.3013782e+09 | G6: 1.4281834e+09 | H6: 1.5929738e+09 | I6: 2.1422751e+09 | J6: 7.4979628e+09 | K6: 1.2551535e+10 | L6: 5.493013e+08 | M6: 5.2183624e+08 | N6: 3.378203e+09 | O6: 4.9162467e+09 | P6: 7.9147693e+09 | Q6: 6.8662663e+08 | R6: 5.2183624e+08 | S6: 5.2732925e+09 | T6: 2.3658278e+09 | U6: 2.0324148e+09 | V6: 2.4169257e+09 | W6: 1.1535327e+09 | X6: 1.6479039e+09 | Y6: 5.7676637e+08 | Z6: 4.7239912e+09 | AA6: 2.8289017e+09 | AB6: 3.1310174e+09 | AC6: 2.2796004e+09 | AD6: 1.2194489e+10 | AE6: 2.7083136e+11 | AF6: 1.4704678e+11 | AG6: 3.6132642e+09 | AH6: 1.1398988e+10 | AI6: 6.1081372e+09 | AJ6: 4.6456254e+09 | AK6: 9.4633111e+08 | AL6: 1.0753763e+09 | AM6: 3.2261288e+09 | AN6: 9.4633111e+08 | AO6: 2.1507525e+09 | AP6: 1.2474365e+09 | AQ6: 1.5116994e+08 | AR6: 4.2327584e+08 | AS6: 3.056279e+08 | AT6: 2.7345654e+08 | AU6: 1.1337746e+08 | AV6: 3.2501538e+08 | AW6: 9.0079803e+08 | AX6: 4.2327584e+08 | AY6: 1.8389293e+08 | AZ6: 1.0005939e+09 | BA6: 3.461514e+08 | BB6: 2.1634462e+08 | BC6: 9.1617803e+08 | BD6: 81129233 | BE6: 6.1366104e+09 | BF6: 1.0162074e+09
A7: 2030 | B7: 1.5208708e+09 | C7: 1.5532297e+09 | D7: 1.3524351e+10 | E7: 9.7076858e+08 | F7: 5.1098581e+09 | G7: 1.6826655e+09 | H7: 1.8768193e+09 | I7: 2.5239983e+09 | J7: 8.8339941e+09 | K7: 1.4788041e+10 | L7: 6.4717906e+08 | M7: 6.148201e+08 | N7: 3.9801512e+09 | O7: 5.7922526e+09 | P7: 9.6080333e+09 | Q7: 8.0897382e+08 | R7: 6.148201e+08 | S7: 6.2129189e+09 | T7: 2.8719665e+09 | U7: 2.3945625e+09 | V7: 2.8475878e+09 | W7: 1.359076e+09 | X7: 1.9415372e+09 | Y7: 6.7953801e+08 | Z7: 5.5657399e+09 | AA7: 3.3329721e+09 | AB7: 3.6889206e+09 | AC7: 2.6857931e+09 | AD7: 1.4367375e+10 | AE7: 3.3061019e+11 | AF7: 1.8399751e+11 | AG7: 4.3862761e+09 | AH7: 1.3837657e+10 | AI7: 7.4148953e+09 | AJ7: 5.6394978e+09 | AK7: 1.1487866e+09 | AL7: 1.3054393e+09 | AM7: 3.9163179e+09 | AN7: 1.1487866e+09 | AO7: 2.6108786e+09 | AP7: 1.5143096e+09 | AQ7: 1.8095597e+08 | AR7: 5.0667673e+08 | AS7: 3.6849001e+08 | AT7: 3.2970159e+08 | AU7: 1.3571698e+08 | AV7: 3.8905534e+08 | AW7: 1.0860758e+09 | AX7: 5.0667673e+08 | AY7: 2.2108947e+08 | AZ7: 1.2029868e+09 | BA7: 4.1616842e+08 | BB7: 2.6010526e+08 | BC7: 1.0883813e+09 | BD7: 97539474 | BE7: 7.355295e+09 | BF7: 1.1972813e+09
A8: 2031 | B8: 1.6699761e+09 | C8: 1.7055075e+09 | D8: 1.5266517e+10 | E8: 1.0659422e+09 | F8: 5.6542737e+09 | G8: 1.8476331e+09 | H8: 2.0608216e+09 | I8: 2.7714497e+09 | J8: 9.7000739e+09 | K8: 1.6237853e+10 | L8: 7.1062813e+08 | M8: 6.7509672e+08 | N8: 4.370363e+09 | O8: 6.3601217e+09 | P8: 1.0845711e+10 | Q8: 8.8828516e+08 | R8: 6.7509672e+08 | S8: 6.82203e+09 | T8: 3.2419244e+09 | U8: 2.6293241e+09 | V8: 3.1267638e+09 | W8: 1.4923191e+09 | X8: 2.1318844e+09 | Y8: 7.4615953e+08 | Z8: 6.1114019e+09 | AA8: 3.6597348e+09 | AB8: 4.0505803e+09 | AC8: 2.9491067e+09 | AD8: 1.5775944e+10 | AE8: 3.7509583e+11 | AF8: 2.1343584e+11 | AG8: 4.9513028e+09 | AH8: 1.5620181e+10 | AI8: 8.3700595e+09 | AJ8: 6.3659607e+09 | AK8: 1.2967698e+09 | AL8: 1.473602e+09 | AM8: 4.4208061e+09 | AN8: 1.2967698e+09 | AO8: 2.947204e+09 | AP8: 1.7093783e+09 | AQ8: 2.0165385e+08 | AR8: 5.6463079e+08 | AS8: 4.1336869e+08 | AT8: 3.6985619e+08 | AU8: 1.5124039e+08 | AV8: 4.3355578e+08 | AW8: 1.2183498e+09 | AX8: 5.6463079e+08 | AY8: 2.4737152e+08 | AZ8: 1.3459921e+09 | BA8: 4.656405e+08 | BB8: 2.9102531e+08 | BC8: 1.2043399e+09 | BD8: 1.0913449e+08 | BE8: 8.2064362e+09 | BF8: 1.314662e+09
A9: 2032 | B9: 1.7123175e+09 | C9: 1.7487498e+09 | D9: 1.6035099e+10 | E9: 1.0929686e+09 | F9: 5.8371214e+09 | G9: 1.894479e+09 | H9: 2.1130727e+09 | I9: 2.8417184e+09 | J9: 9.9460145e+09 | K9: 1.6649555e+10 | L9: 7.2864575e+08 | M9: 6.9221347e+08 | N9: 4.4811714e+09 | O9: 6.5213795e+09 | P9: 1.1391731e+10 | Q9: 9.1080719e+08 | R9: 6.9221347e+08 | S9: 6.9949992e+09 | T9: 3.4051369e+09 | U9: 2.6959893e+09 | V9: 3.2060413e+09 | W9: 1.5301561e+09 | X9: 2.1859373e+09 | Y9: 7.6507804e+08 | Z9: 6.2663535e+09 | AA9: 3.7525256e+09 | AB9: 4.1532808e+09 | AC9: 3.0238799e+09 | AD9: 1.6175936e+10 | AE9: 3.9569468e+11 | AF9: 2.2941101e+11 | AG9: 5.2005727e+09 | AH9: 1.6406569e+10 | AI9: 8.7914444e+09 | AJ9: 6.6864507e+09 | AK9: 1.3620548e+09 | AL9: 1.5477895e+09 | AM9: 4.6433685e+09 | AN9: 1.3620548e+09 | AO9: 3.095579e+09 | AP9: 1.7954358e+09 | AQ9: 2.0946229e+08 | AR9: 5.864944e+08 | AS9: 4.3185019e+08 | AT9: 3.8639228e+08 | AU9: 1.5709671e+08 | AV9: 4.5034391e+08 | AW9: 1.2728216e+09 | AX9: 5.864944e+08 | AY9: 2.5784995e+08 | AZ9: 1.4030071e+09 | BA9: 4.8536461e+08 | BB9: 3.0335288e+08 | BC9: 1.2432858e+09 | BD9: 1.1375733e+08 | BE9: 8.533102e+09 | BF9: 1.3479946e+09
A10: 2033 | B10: 1.688342e+09 | C10: 1.7242641e+09 | D10: 1.6093328e+10 | E10: 1.0776651e+09 | F10: 5.7842919e+09 | G10: 1.8679528e+09 | H10: 2.0834858e+09 | I10: 2.8019292e+09 | J10: 9.8067522e+09 | K10: 1.6416431e+10 | L10: 7.1844339e+08 | M10: 6.8252122e+08 | N10: 4.4184268e+09 | O10: 6.4300683e+09 | P10: 1.1433098e+10 | Q10: 8.9805423e+08 | R10: 6.8252122e+08 | S10: 6.8970565e+09 | T10: 3.417502e+09 | U10: 2.6582405e+09 | V10: 3.1611509e+09 | W10: 1.5087311e+09 | X10: 2.1553302e+09 | Y10: 7.5436556e+08 | Z10: 6.1786131e+09 | AA10: 3.6999834e+09 | AB10: 4.0951273e+09 | AC10: 2.9815401e+09 | AD10: 1.5949443e+10 | AE10: 3.9839823e+11 | AF10: 2.341601e+11 | AG10: 5.2194576e+09 | AH10: 1.6466146e+10 | AI10: 8.8233688e+09 | AJ10: 6.7107312e+09 | AK10: 1.3670008e+09 | AL10: 1.55341e+09 | AM10: 4.66023e+09 | AN10: 1.3670008e+09 | AO10: 3.10682e+09 | AP10: 1.8019556e+09 | AQ10: 2.0851121e+08 | AR10: 5.8383139e+08 | AS10: 4.3171009e+08 | AT10: 3.8626692e+08 | AU10: 1.5638341e+08 | AV10: 4.482991e+08 | AW10: 1.2724087e+09 | AX10: 5.8383139e+08 | AY10: 2.5733995e+08 | AZ10: 1.4002321e+09 | BA10: 4.8440461e+08 | BB10: 3.0275288e+08 | BC10: 1.2320333e+09 | BD10: 1.1353233e+08 | BE10: 8.5008792e+09 | BF10: 1.3291203e+09
A11: 2034 | B11: 1.6031981e+09 | C11: 1.6373087e+09 | D11: 1.5448157e+10 | E11: 1.0233179e+09 | F11: 5.5093779e+09 | G11: 1.7737511e+09 | H11: 1.9784146e+09 | I11: 2.6606266e+09 | J11: 9.3121931e+09 | K11: 1.5588543e+10 | L11: 6.8221195e+08 | M11: 6.4810135e+08 | N11: 4.1956035e+09 | O11: 6.1057969e+09 | P11: 1.0974752e+10 | Q11: 8.5276493e+08 | R11: 6.4810135e+08 | S11: 6.5492347e+09 | T11: 3.2804966e+09 | U11: 2.5241842e+09 | V11: 3.0017326e+09 | W11: 1.4326451e+09 | X11: 2.0466358e+09 | Y11: 7.1632255e+08 | Z11: 5.8670228e+09 | AA11: 3.5133915e+09 | AB11: 3.8886081e+09 | AC11: 2.8311796e+09 | AD11: 1.5145105e+10 | AE11: 3.831752e+11 | AF11: 2.2712073e+11 | AG11: 5.010213e+09 | AH11: 1.5806029e+10 | AI11: 8.4696457e+09 | AJ11: 6.4417024e+09 | AK11: 1.3121986e+09 | AL11: 1.4911348e+09 | AM11: 4.4734044e+09 | AN11: 1.3121986e+09 | AO11: 2.9822696e+09 | AP11: 1.7297164e+09 | AQ11: 1.9915258e+08 | AR11: 5.5762724e+08 | AS11: 4.1340118e+08 | AT11: 3.6988527e+08 | AU11: 1.4936444e+08 | AV11: 4.2817806e+08 | AW11: 1.2184456e+09 | AX11: 5.5762724e+08 | AY11: 2.4617652e+08 | AZ11: 1.3394899e+09 | BA11: 4.633911e+08 | BB11: 2.8961944e+08 | BC11: 1.1734776e+09 | BD11: 1.0860729e+08 | BE11: 8.1231442e+09 | BF11: 1.2620921e+09
A12: 2035 | B12: 1.4617041e+09 | C12: 1.4928042e+09 | D12: 1.4129211e+10 | E12: 9.3300261e+08 | F12: 5.0275865e+09 | G12: 1.6172045e+09 | H12: 1.803805e+09 | I12: 2.4258068e+09 | J12: 8.4903237e+09 | K12: 1.421274e+10 | L12: 6.2200174e+08 | M12: 5.9090165e+08 | N12: 3.8253107e+09 | O12: 5.5669156e+09 | P12: 1.0037741e+10 | Q12: 7.7750217e+08 | R12: 5.9090165e+08 | S12: 5.9712167e+09 | T12: 3.0004116e+09 | U12: 2.3014064e+09 | V12: 2.7368076e+09 | W12: 1.3062037e+09 | X12: 1.8660052e+09 | Y12: 6.5310183e+08 | Z12: 5.349215e+09 | AA12: 3.203309e+09 | AB12: 3.5454099e+09 | AC12: 2.5813072e+09 | AD12: 1.3808439e+10 | AE12: 3.5066055e+11 | AF12: 2.0836351e+11 | AG12: 4.5824469e+09 | AH12: 1.4456529e+10 | AI12: 7.7465173e+09 | AJ12: 5.8917174e+09 | AK12: 1.2001647e+09 | AL12: 1.3638235e+09 | AM12: 4.0914704e+09 | AN12: 1.2001647e+09 | AO12: 2.7276469e+09 | AP12: 1.5820352e+09 | AQ12: 1.8188343e+08 | AR12: 5.092736e+08 | AS12: 3.778384e+08 | AT12: 3.3806594e+08 | AU12: 1.3641257e+08 | AV12: 3.9104937e+08 | AW12: 1.113629e+09 | AX12: 5.092736e+08 | AY12: 2.2493276e+08 | AZ12: 1.2238988e+09 | BA12: 4.2340284e+08 | BB12: 2.6462678e+08 | BC12: 1.0708578e+09 | BD12: 99235041 | BE12: 7.4197739e+09 | BF12: 1.1507032e+09
A14: Solar Capacity (MW) | BH14: Total Solar Capacity (GW)
A16: 2028 | B16: =B5/'Output-Calculation-sheet'!B4*'Output-Calculation-sheet'!B22 -> 0 | C16: =C5/'Output-Calculation-sheet'!C4*'Output-Calculation-sheet'!C22 -> 0 | D16: =D5/'Output-Calculation-sheet'!D4*'Output-Calculation-sheet'!D22 -> 91.321186 | E16: =E5/'Output-Calculation-sheet'!E4*'Output-Calculation-sheet'!E22 -> 5.796967 | F16: =F5/'Output-Calculation-sheet'!F4*'Output-Calculation-sheet'!F22 -> 26.729126 | G16: =G5/'Output-Calculation-sheet'!G4*'Output-Calculation-sheet'!G22 -> 0 | H16: =H5/'Output-Calculation-sheet'!H4*'Output-Calculation-sheet'!H22 -> 0 | I16: =I5/'Output-Calculation-sheet'!I4*'Output-Calculation-sheet'!I22 -> 0 | ... BF16: =BF5/'Output-Calculation-sheet'!BF4*'Output-Calculation-sheet'!BF22 -> 0 | BH16: =SUM(B16:BF16)/1000 -> 13.027685
A17: 2029 | B17: =B6/'Output-Calculation-sheet'!B5*'Output-Calculation-sheet'!B23 -> 0 | C17: =C6/'Output-Calculation-sheet'!C5*'Output-Calculation-sheet'!C23 -> 0 | D17: =D6/'Output-Calculation-sheet'!D5*'Output-Calculation-sheet'!D23 -> 186.19916 | E17: =E6/'Output-Calculation-sheet'!E5*'Output-Calculation-sheet'!E23 -> 12.192478 | F17: =F6/'Output-Calculation-sheet'!F5*'Output-Calculation-sheet'!F23 -> 59.410612 | G17: =G6/'Output-Calculation-sheet'!G5*'Output-Calculation-sheet'!G23 -> 0 | H17: =H6/'Output-Calculation-sheet'!H5*'Output-Calculation-sheet'!H23 -> 0 | I17: =I6/'Output-Calculation-sheet'!I5*'Output-Calculation-sheet'!I23 -> 0 | ... BF17: =BF6/'Output-Calculation-sheet'!BF5*'Output-Calculation-sheet'!BF23 -> 0 | BH17: =SUM(B17:BF17)/1000 -> 30.869322
A18: 2030 | B18: =B7/'Output-Calculation-sheet'!B6*'Output-Calculation-sheet'!B24 -> 0 | C18: =C7/'Output-Calculation-sheet'!C6*'Output-Calculation-sheet'!C24 -> 0 | D18: =D7/'Output-Calculation-sheet'!D6*'Output-Calculation-sheet'!D24 -> 239.40373 | E18: =E7/'Output-Calculation-sheet'!E6*'Output-Calculation-sheet'!E24 -> 17.05057 | F18: =F7/'Output-Calculation-sheet'!F6*'Output-Calculation-sheet'!F24 -> 88.389945 | G18: =G7/'Output-Calculation-sheet'!G6*'Output-Calculation-sheet'!G24 -> 0 | H18: =H7/'Output-Calculation-sheet'!H6*'Output-Calculation-sheet'!H24 -> 0 | I18: =I7/'Output-Calculation-sheet'!I6*'Output-Calculation-sheet'!I24 -> 0 | ... BF18: =BF7/'Output-Calculation-sheet'!BF6*'Output-Calculation-sheet'!BF24 -> 0 | BH18: =SUM(B18:BF18)/1000 -> 48.438163
A19: 2031 | B19: =B8/'Output-Calculation-sheet'!B7*'Output-Calculation-sheet'!B25 -> 0 | C19: =C8/'Output-Calculation-sheet'!C7*'Output-Calculation-sheet'!C25 -> 0 | D19: =D8/'Output-Calculation-sheet'!D7*'Output-Calculation-sheet'!D25 -> 195.02318 | E19: =E8/'Output-Calculation-sheet'!E7*'Output-Calculation-sheet'!E25 -> 0 | F19: =F8/'Output-Calculation-sheet'!F7*'Output-Calculation-sheet'!F25 -> 94.105252 | G19: =G8/'Output-Calculation-sheet'!G7*'Output-Calculation-sheet'!G25 -> 0 | H19: =H8/'Output-Calculation-sheet'!H7*'Output-Calculation-sheet'!H25 -> 0 | I19: =I8/'Output-Calculation-sheet'!I7*'Output-Calculation-sheet'!I25 -> 0 | ... BF19: =BF8/'Output-Calculation-sheet'!BF7*'Output-Calculation-sheet'!BF25 -> 0 | BH19: =SUM(B19:BF19)/1000 -> 60.485761
A20: 2032 | B20: =B9/'Output-Calculation-sheet'!B8*'Output-Calculation-sheet'!B26 -> 0 | C20: =C9/'Output-Calculation-sheet'!C8*'Output-Calculation-sheet'!C26 -> 0 | D20: =D9/'Output-Calculation-sheet'!D8*'Output-Calculation-sheet'!D26 -> 68.522792 | E20: =E9/'Output-Calculation-sheet'!E8*'Output-Calculation-sheet'!E26 -> 0 | F20: =F9/'Output-Calculation-sheet'!F8*'Output-Calculation-sheet'!F26 -> 75.480825 | G20: =G9/'Output-Calculation-sheet'!G8*'Output-Calculation-sheet'!G26 -> 0 | H20: =H9/'Output-Calculation-sheet'!H8*'Output-Calculation-sheet'!H26 -> 0 | I20: =I9/'Output-Calculation-sheet'!I8*'Output-Calculation-sheet'!I26 -> 0 | ... BF20: =BF9/'Output-Calculation-sheet'!BF8*'Output-Calculation-sheet'!BF26 -> 0 | BH20: =SUM(B20:BF20)/1000 -> 63.415341
A21: 2033 | B21: =B10/'Output-Calculation-sheet'!B9*'Output-Calculation-sheet'!B27 -> 0 | C21: =C10/'Output-Calculation-sheet'!C9*'Output-Calculation-sheet'!C27 -> 0 | D21: =D10/'Output-Calculation-sheet'!D9*'Output-Calculation-sheet'!D27 -> 0 | E21: =E10/'Output-Calculation-sheet'!E9*'Output-Calculation-sheet'!E27 -> 0 | F21: =F10/'Output-Calculation-sheet'!F9*'Output-Calculation-sheet'!F27 -> 34.106467 | G21: =G10/'Output-Calculation-sheet'!G9*'Output-Calculation-sheet'!G27 -> 0 | H21: =H10/'Output-Calculation-sheet'!H9*'Output-Calculation-sheet'!H27 -> 0 | I21: =I10/'Output-Calculation-sheet'!I9*'Output-Calculation-sheet'!I27 -> 0 | ... BF21: =BF10/'Output-Calculation-sheet'!BF9*'Output-Calculation-sheet'!BF27 -> 0 | BH21: =SUM(B21:BF21)/1000 -> 58.477869
A22: 2034 | B22: =B11/'Output-Calculation-sheet'!B10*'Output-Calculation-sheet'!B28 -> 43.13755 | C22: =C11/'Output-Calculation-sheet'!C10*'Output-Calculation-sheet'!C28 -> 0 | D22: =D11/'Output-Calculation-sheet'!D10*'Output-Calculation-sheet'!D28 -> 0 | E22: =E11/'Output-Calculation-sheet'!E10*'Output-Calculation-sheet'!E28 -> 0 | F22: =F11/'Output-Calculation-sheet'!F10*'Output-Calculation-sheet'!F28 -> 0 | G22: =G11/'Output-Calculation-sheet'!G10*'Output-Calculation-sheet'!G28 -> 0 | H22: =H11/'Output-Calculation-sheet'!H10*'Output-Calculation-sheet'!H28 -> 0 | I22: =I11/'Output-Calculation-sheet'!I10*'Output-Calculation-sheet'!I28 -> 46.556117 | ... BF22: =BF11/'Output-Calculation-sheet'!BF10*'Output-Calculation-sheet'!BF28 -> 0 | BH22: =SUM(B22:BF22)/1000 -> 45.392963
A23: 2035 | B23: =B12/'Output-Calculation-sheet'!B11*'Output-Calculation-sheet'!B29 -> 150.72372 | C23: =C12/'Output-Calculation-sheet'!C11*'Output-Calculation-sheet'!C29 -> 0 | D23: =D12/'Output-Calculation-sheet'!D11*'Output-Calculation-sheet'!D29 -> 0 | E23: =E12/'Output-Calculation-sheet'!E11*'Output-Calculation-sheet'!E29 -> 0 | F23: =F12/'Output-Calculation-sheet'!F11*'Output-Calculation-sheet'!F29 -> 0 | G23: =G12/'Output-Calculation-sheet'!G11*'Output-Calculation-sheet'!G29 -> 0 | H23: =H12/'Output-Calculation-sheet'!H11*'Output-Calculation-sheet'!H29 -> 0 | I23: =I12/'Output-Calculation-sheet'!I11*'Output-Calculation-sheet'!I29 -> 282.72511 | ... BF23: =BF12/'Output-Calculation-sheet'!BF11*'Output-Calculation-sheet'!BF29 -> 0 | BH23: =SUM(B23:BF23)/1000 -> 27.547146
A25: Wind Capacity (MW) | BH25: Total Wind Capacity (GW)
A27: 2028 | B27: =B5/'Output-Calculation-sheet'!B4*'Output-Calculation-sheet'!B13 -> 34.443569 | C27: =C5/'Output-Calculation-sheet'!C4*'Output-Calculation-sheet'!C13 -> 16.444575 | D27: =D5/'Output-Calculation-sheet'!D4*'Output-Calculation-sheet'!D13 -> 86.048702 | E27: =E5/'Output-Calculation-sheet'!E4*'Output-Calculation-sheet'!E13 -> 13.039395 | F27: =F5/'Output-Calculation-sheet'!F4*'Output-Calculation-sheet'!F13 -> 45.743031 | G27: =G5/'Output-Calculation-sheet'!G4*'Output-Calculation-sheet'!G13 -> 20.125443 | H27: =H5/'Output-Calculation-sheet'!H4*'Output-Calculation-sheet'!H13 -> 16.521109 | I27: =I5/'Output-Calculation-sheet'!I4*'Output-Calculation-sheet'!I13 -> 64.852982 | ... BF27: =BF5/'Output-Calculation-sheet'!BF4*'Output-Calculation-sheet'!BF13 -> 11.118329 | BH27: =SUM(B27:BF27)/1000 -> 5.1061735
A28: 2029 | B28: =B6/'Output-Calculation-sheet'!B5*'Output-Calculation-sheet'!B14 -> 88.557002 | C28: =C6/'Output-Calculation-sheet'!C5*'Output-Calculation-sheet'!C14 -> 42.280236 | D28: =D6/'Output-Calculation-sheet'!D5*'Output-Calculation-sheet'!D14 -> 245.42315 | E28: =E6/'Output-Calculation-sheet'!E5*'Output-Calculation-sheet'!E14 -> 34.309366 | F28: =F6/'Output-Calculation-sheet'!F5*'Output-Calculation-sheet'!F14 -> 122.84677 | G28: =G6/'Output-Calculation-sheet'!G5*'Output-Calculation-sheet'!G14 -> 51.744025 | H28: =H6/'Output-Calculation-sheet'!H5*'Output-Calculation-sheet'!H14 -> 42.477011 | I28: =I6/'Output-Calculation-sheet'!I5*'Output-Calculation-sheet'!I14 -> 166.73798 | ... BF28: =BF6/'Output-Calculation-sheet'!BF5*'Output-Calculation-sheet'!BF14 -> 28.586058 | BH28: =SUM(B28:BF28)/1000 -> 14.352098
A29: 2030 | B29: =B7/'Output-Calculation-sheet'!B6*'Output-Calculation-sheet'!B15 -> 156.50492 | C29: =C7/'Output-Calculation-sheet'!C6*'Output-Calculation-sheet'!C15 -> 74.720967 | D29: =D7/'Output-Calculation-sheet'!D6*'Output-Calculation-sheet'!D15 -> 478.94894 | E29: =E7/'Output-Calculation-sheet'!E6*'Output-Calculation-sheet'!E15 -> 61.934054 | F29: =F7/'Output-Calculation-sheet'!F6*'Output-Calculation-sheet'!F15 -> 226.55072 | G29: =G7/'Output-Calculation-sheet'!G6*'Output-Calculation-sheet'!G15 -> 91.446121 | H29: =H7/'Output-Calculation-sheet'!H6*'Output-Calculation-sheet'!H15 -> 75.065059 | I29: =I7/'Output-Calculation-sheet'!I6*'Output-Calculation-sheet'!I15 -> 295.01953 | ... BF29: =BF7/'Output-Calculation-sheet'!BF6*'Output-Calculation-sheet'!BF15 -> 50.519536 | BH29: =SUM(B29:BF29)/1000 -> 27.831086
A30: 2031 | B30: =B8/'Output-Calculation-sheet'!B7*'Output-Calculation-sheet'!B16 -> 235.11371 | C30: =C8/'Output-Calculation-sheet'!C7*'Output-Calculation-sheet'!C16 -> 109.39249 | D30: =D8/'Output-Calculation-sheet'!D7*'Output-Calculation-sheet'!D16 -> 774.05066 | E30: =E8/'Output-Calculation-sheet'!E7*'Output-Calculation-sheet'!E16 -> 97.894904 | F30: =F8/'Output-Calculation-sheet'!F7*'Output-Calculation-sheet'!F16 -> 350.12934 | G30: =G8/'Output-Calculation-sheet'!G7*'Output-Calculation-sheet'!G16 -> 133.88556 | H30: =H8/'Output-Calculation-sheet'!H7*'Output-Calculation-sheet'!H16 -> 109.90053 | I30: =I8/'Output-Calculation-sheet'!I7*'Output-Calculation-sheet'!I16 -> 438.02744 | ... BF30: =BF8/'Output-Calculation-sheet'!BF7*'Output-Calculation-sheet'!BF16 -> 73.963257 | BH30: =SUM(B30:BF30)/1000 -> 45.569961
A31: 2032 | B31: =B9/'Output-Calculation-sheet'!B8*'Output-Calculation-sheet'!B17 -> 321.30758 | C31: =C9/'Output-Calculation-sheet'!C8*'Output-Calculation-sheet'!C17 -> 140.20836 | D31: =D9/'Output-Calculation-sheet'!D8*'Output-Calculation-sheet'!D17 -> 1076.599 | E31: =E9/'Output-Calculation-sheet'!E8*'Output-Calculation-sheet'!E17 -> 125.64906 | F31: =F9/'Output-Calculation-sheet'!F8*'Output-Calculation-sheet'!F17 -> 471.93591 | G31: =G9/'Output-Calculation-sheet'!G8*'Output-Calculation-sheet'!G17 -> 171.59928 | H31: =H9/'Output-Calculation-sheet'!H8*'Output-Calculation-sheet'!H17 -> 140.85979 | I31: =I9/'Output-Calculation-sheet'!I8*'Output-Calculation-sheet'!I17 -> 579.6839 | ... BF31: =BF9/'Output-Calculation-sheet'!BF8*'Output-Calculation-sheet'!BF17 -> 94.798199 | BH31: =SUM(B31:BF31)/1000 -> 64.272723
A32: 2033 | B32: =B10/'Output-Calculation-sheet'!B9*'Output-Calculation-sheet'!B18 -> 420.05716 | C32: =C10/'Output-Calculation-sheet'!C9*'Output-Calculation-sheet'!C18 -> 165.89482 | D32: =D10/'Output-Calculation-sheet'!D9*'Output-Calculation-sheet'!D18 -> 1323.1592 | E32: =E10/'Output-Calculation-sheet'!E9*'Output-Calculation-sheet'!E18 -> 157.88743 | F32: =F10/'Output-Calculation-sheet'!F9*'Output-Calculation-sheet'!F18 -> 585.56448 | G32: =G10/'Output-Calculation-sheet'!G9*'Output-Calculation-sheet'!G18 -> 203.03515 | H32: =H10/'Output-Calculation-sheet'!H9*'Output-Calculation-sheet'!H18 -> 166.66581 | I32: =I10/'Output-Calculation-sheet'!I9*'Output-Calculation-sheet'!I18 -> 723.41375 | ... BF32: =BF10/'Output-Calculation-sheet'!BF9*'Output-Calculation-sheet'!BF18 -> 112.16502 | BH32: =SUM(B32:BF32)/1000 -> 83.002514
A33: 2034 | B33: =B11/'Output-Calculation-sheet'!B10*'Output-Calculation-sheet'!B19 -> 474.68947 | C33: =C11/'Output-Calculation-sheet'!C10*'Output-Calculation-sheet'!C19 -> 184.11034 | D33: =D11/'Output-Calculation-sheet'!D10*'Output-Calculation-sheet'!D19 -> 1481.8139 | E33: =E11/'Output-Calculation-sheet'!E10*'Output-Calculation-sheet'!E19 -> 192.49783 | F33: =F11/'Output-Calculation-sheet'!F10*'Output-Calculation-sheet'!F19 -> 681.6965 | G33: =G11/'Output-Calculation-sheet'!G10*'Output-Calculation-sheet'!G19 -> 244.74728 | H33: =H11/'Output-Calculation-sheet'!H10*'Output-Calculation-sheet'!H19 -> 184.63822 | I33: =I11/'Output-Calculation-sheet'!I10*'Output-Calculation-sheet'!I19 -> 841.0431 | ... BF33: =BF11/'Output-Calculation-sheet'!BF10*'Output-Calculation-sheet'!BF19 -> 124.25742 | BH33: =SUM(B33:BF33)/1000 -> 100.46731
A34: 2035 | B34: =B12/'Output-Calculation-sheet'!B11*'Output-Calculation-sheet'!B20 -> 429.20427 | C34: =C12/'Output-Calculation-sheet'!C11*'Output-Calculation-sheet'!C20 -> 226.66721 | D34: =D12/'Output-Calculation-sheet'!D11*'Output-Calculation-sheet'!D20 -> 1552.2978 | E34: =E12/'Output-Calculation-sheet'!E11*'Output-Calculation-sheet'!E20 -> 225.44437 | F34: =F12/'Output-Calculation-sheet'!F11*'Output-Calculation-sheet'!F20 -> 766.51988 | G34: =G12/'Output-Calculation-sheet'!G11*'Output-Calculation-sheet'!G20 -> 304.84959 | H34: =H12/'Output-Calculation-sheet'!H11*'Output-Calculation-sheet'!H20 -> 192.38845 | I34: =I12/'Output-Calculation-sheet'!I11*'Output-Calculation-sheet'!I20 -> 839.6585 | ... BF34: =BF12/'Output-Calculation-sheet'!BF11*'Output-Calculation-sheet'!BF20 -> 129.47552 | BH34: =SUM(B34:BF34)/1000 -> 115.16198
A36: DAC Capacity (ktCO2/yr) | BH36: Total DAC Capacity (ktCO2/yr)
A38: 2028 | B38: =B5/'Output-Calculation-sheet'!B4*'Output-Calculation-sheet'!B31*0.0114 -> 0 | C38: =C5/'Output-Calculation-sheet'!C4*'Output-Calculation-sheet'!C31*0.0114 -> 0 | D38: =D5/'Output-Calculation-sheet'!D4*'Output-Calculation-sheet'!D31*0.0114 -> 0 | E38: =E5/'Output-Calculation-sheet'!E4*'Output-Calculation-sheet'!E31*0.0114 -> 0 | F38: =F5/'Output-Calculation-sheet'!F4*'Output-Calculation-sheet'!F31*0.0114 -> 0 | G38: =G5/'Output-Calculation-sheet'!G4*'Output-Calculation-sheet'!G31*0.0114 -> 0 | H38: =H5/'Output-Calculation-sheet'!H4*'Output-Calculation-sheet'!H31*0.0114 -> 0 | I38: =I5/'Output-Calculation-sheet'!I4*'Output-Calculation-sheet'!I31*0.0114 -> 0 | ... BF38: =BF5/'Output-Calculation-sheet'!BF4*'Output-Calculation-sheet'!BF31*0.0114 -> 0 | BH38: =SUM(B38:BF38) -> 5.4425413
A39: 2029 | B39: =B6/'Output-Calculation-sheet'!B5*'Output-Calculation-sheet'!B32*0.0114 -> 0 | C39: =C6/'Output-Calculation-sheet'!C5*'Output-Calculation-sheet'!C32*0.0114 -> 0 | D39: =D6/'Output-Calculation-sheet'!D5*'Output-Calculation-sheet'!D32*0.0114 -> 0 | E39: =E6/'Output-Calculation-sheet'!E5*'Output-Calculation-sheet'!E32*0.0114 -> 0 | F39: =F6/'Output-Calculation-sheet'!F5*'Output-Calculation-sheet'!F32*0.0114 -> 0 | G39: =G6/'Output-Calculation-sheet'!G5*'Output-Calculation-sheet'!G32*0.0114 -> 0 | H39: =H6/'Output-Calculation-sheet'!H5*'Output-Calculation-sheet'!H32*0.0114 -> 0 | I39: =I6/'Output-Calculation-sheet'!I5*'Output-Calculation-sheet'!I32*0.0114 -> 0 | ... BF39: =BF6/'Output-Calculation-sheet'!BF5*'Output-Calculation-sheet'!BF32*0.0114 -> 0 | BH39: =SUM(B39:BF39) -> 12.108963
A40: 2030 | B40: =B7/'Output-Calculation-sheet'!B6*'Output-Calculation-sheet'!B33*0.0114 -> 0 | C40: =C7/'Output-Calculation-sheet'!C6*'Output-Calculation-sheet'!C33*0.0114 -> 0 | D40: =D7/'Output-Calculation-sheet'!D6*'Output-Calculation-sheet'!D33*0.0114 -> 0 | E40: =E7/'Output-Calculation-sheet'!E6*'Output-Calculation-sheet'!E33*0.0114 -> 0 | F40: =F7/'Output-Calculation-sheet'!F6*'Output-Calculation-sheet'!F33*0.0114 -> 0 | G40: =G7/'Output-Calculation-sheet'!G6*'Output-Calculation-sheet'!G33*0.0114 -> 0 | H40: =H7/'Output-Calculation-sheet'!H6*'Output-Calculation-sheet'!H33*0.0114 -> 0 | I40: =I7/'Output-Calculation-sheet'!I6*'Output-Calculation-sheet'!I33*0.0114 -> 0 | ... BF40: =BF7/'Output-Calculation-sheet'!BF6*'Output-Calculation-sheet'!BF33*0.0114 -> 0 | BH40: =SUM(B40:BF40) -> 30.548711
A41: 2031 | B41: =B8/'Output-Calculation-sheet'!B7*'Output-Calculation-sheet'!B34*0.0114 -> 0 | C41: =C8/'Output-Calculation-sheet'!C7*'Output-Calculation-sheet'!C34*0.0114 -> 0 | D41: =D8/'Output-Calculation-sheet'!D7*'Output-Calculation-sheet'!D34*0.0114 -> 0 | E41: =E8/'Output-Calculation-sheet'!E7*'Output-Calculation-sheet'!E34*0.0114 -> 0 | F41: =F8/'Output-Calculation-sheet'!F7*'Output-Calculation-sheet'!F34*0.0114 -> 0 | G41: =G8/'Output-Calculation-sheet'!G7*'Output-Calculation-sheet'!G34*0.0114 -> 0 | H41: =H8/'Output-Calculation-sheet'!H7*'Output-Calculation-sheet'!H34*0.0114 -> 0 | I41: =I8/'Output-Calculation-sheet'!I7*'Output-Calculation-sheet'!I34*0.0114 -> 0 | ... BF41: =BF8/'Output-Calculation-sheet'!BF7*'Output-Calculation-sheet'!BF34*0.0114 -> 0 | BH41: =SUM(B41:BF41) -> 16.486708
A42: 2032 | B42: =B9/'Output-Calculation-sheet'!B8*'Output-Calculation-sheet'!B35*0.0114 -> 0 | C42: =C9/'Output-Calculation-sheet'!C8*'Output-Calculation-sheet'!C35*0.0114 -> 0 | D42: =D9/'Output-Calculation-sheet'!D8*'Output-Calculation-sheet'!D35*0.0114 -> 0 | E42: =E9/'Output-Calculation-sheet'!E8*'Output-Calculation-sheet'!E35*0.0114 -> 0 | F42: =F9/'Output-Calculation-sheet'!F8*'Output-Calculation-sheet'!F35*0.0114 -> 0 | G42: =G9/'Output-Calculation-sheet'!G8*'Output-Calculation-sheet'!G35*0.0114 -> 0 | H42: =H9/'Output-Calculation-sheet'!H8*'Output-Calculation-sheet'!H35*0.0114 -> 0 | I42: =I9/'Output-Calculation-sheet'!I8*'Output-Calculation-sheet'!I35*0.0114 -> 0 | ... BF42: =BF9/'Output-Calculation-sheet'!BF8*'Output-Calculation-sheet'!BF35*0.0114 -> 0 | BH42: =SUM(B42:BF42) -> 12.26271
A43: 2033 | B43: =B10/'Output-Calculation-sheet'!B9*'Output-Calculation-sheet'!B36*0.0114 -> 0 | C43: =C10/'Output-Calculation-sheet'!C9*'Output-Calculation-sheet'!C36*0.0114 -> 0 | D43: =D10/'Output-Calculation-sheet'!D9*'Output-Calculation-sheet'!D36*0.0114 -> 0 | E43: =E10/'Output-Calculation-sheet'!E9*'Output-Calculation-sheet'!E36*0.0114 -> 0 | F43: =F10/'Output-Calculation-sheet'!F9*'Output-Calculation-sheet'!F36*0.0114 -> 0 | G43: =G10/'Output-Calculation-sheet'!G9*'Output-Calculation-sheet'!G36*0.0114 -> 0 | H43: =H10/'Output-Calculation-sheet'!H9*'Output-Calculation-sheet'!H36*0.0114 -> 0 | I43: =I10/'Output-Calculation-sheet'!I9*'Output-Calculation-sheet'!I36*0.0114 -> 0 | ... BF43: =BF10/'Output-Calculation-sheet'!BF9*'Output-Calculation-sheet'!BF36*0.0114 -> 0 | BH43: =SUM(B43:BF43) -> 0.27034753
